Traceback (most recent call last):
  File "c:\users\user\appdata\local\programs\python\python39\lib\site-packages\jupyter_cache\executors\utils.py", line 51, in single_nb_execution
    executenb(
  File "c:\users\user\appdata\local\programs\python\python39\lib\site-packages\nbclient\client.py", line 1112, in execute
    return NotebookClient(nb=nb, resources=resources, km=km, **kwargs).execute()
  File "c:\users\user\appdata\local\programs\python\python39\lib\site-packages\nbclient\util.py", line 74, in wrapped
    return just_run(coro(*args, **kwargs))
  File "c:\users\user\appdata\local\programs\python\python39\lib\site-packages\nbclient\util.py", line 53, in just_run
    return loop.run_until_complete(coro)
  File "c:\users\user\appdata\local\programs\python\python39\lib\asyncio\base_events.py", line 642, in run_until_complete
    return future.result()
  File "c:\users\user\appdata\local\programs\python\python39\lib\site-packages\nbclient\client.py", line 553, in async_execute
    await self.async_execute_cell(
  File "c:\users\user\appdata\local\programs\python\python39\lib\site-packages\nbclient\client.py", line 857, in async_execute_cell
    self._check_raise_for_error(cell, exec_reply)
  File "c:\users\user\appdata\local\programs\python\python39\lib\site-packages\nbclient\client.py", line 760, in _check_raise_for_error
    raise CellExecutionError.from_cell_and_msg(cell, exec_reply_content)
nbclient.exceptions.CellExecutionError: An error occurred while executing the following cell:
------------------
import numpy as np
import matplotlib.pyplot as plt
%matplotlib inline

# Fixing random state for reproducibility
np.random.seed(19680801)

# Compute pie slices
N = 20
Î¸ = np.linspace(0.0, 2 * np.pi, N, endpoint=False)
radii = 10 * np.random.rand(N)
width = np.pi / 4 * np.random.rand(N)
colors = plt.cm.viridis(radii / 10.)

ax = plt.subplot(111, projection='polar')
ax.bar(Î¸, radii, width=width, bottom=0.0, color=colors, alpha=0.5)

plt.show()
------------------

[1;31m---------------------------------------------------------------------------[0m
[1;31mModuleNotFoundError[0m                       Traceback (most recent call last)
[1;32m~\AppData\Local\Temp/ipykernel_28292/3780265214.py[0m in [0;36m<module>[1;34m[0m
[1;32m----> 1[1;33m [1;32mimport[0m [0mnumpy[0m [1;32mas[0m [0mnp[0m[1;33m[0m[1;33m[0m[0m
[0m[0;32m      2[0m [1;32mimport[0m [0mmatplotlib[0m[1;33m.[0m[0mpyplot[0m [1;32mas[0m [0mplt[0m[1;33m[0m[1;33m[0m[0m
[0;32m      3[0m [0mget_ipython[0m[1;33m([0m[1;33m)[0m[1;33m.[0m[0mrun_line_magic[0m[1;33m([0m[1;34m'matplotlib'[0m[1;33m,[0m [1;34m'inline'[0m[1;33m)[0m[1;33m[0m[1;33m[0m[0m
[0;32m      4[0m [1;33m[0m[0m
[0;32m      5[0m [1;31m# Fixing random state for reproducibility[0m[1;33m[0m[1;33m[0m[1;33m[0m[0m

[1;31mModuleNotFoundError[0m: No module named 'numpy'
ModuleNotFoundError: No module named 'numpy'

